Workbook

Sheet Resumen
A1: EVALUACIÓN ECONÓMICA — PIZZERÍA B2B
A2: Flujo libre sin deuda · CLP nominales · 5 años
A4: Decisión del escenario activo
A6: Inversión inicial | B6: =Calculos!$B$46 -> 38467030 | D6: Escenario | E6: =Inputs!$C$5 -> Base
A7: Fondeo máximo | B7: =Calculos!$B$51 -> 1.2549356e+08 | D7: TMAR | E7: =Inputs!$C$6 -> 0.2046
A8: VAN | B8: =Calculos!$B$47 -> -91764381 | D8: Capital disponible | E8: =Inputs!$C$8 -> 50000000
A9: TIR | B9: =Calculos!$B$48 -> #N/A
A10: Payback descontado | B10: =Calculos!$B$49 -> #N/A | D10: Dictamen | E10: =IF(AND(Resumen!$B$8>0,IF(ISNA(Resumen!$B$9),FALSE(),Resumen!$B$9>Inputs!$C$6),Resumen!$B$7<=Inputs!$C$8),"VIABLE · SUPUESTOS","RECHAZAR / REDISEÑAR") -> RECHAZAR / REDISEÑAR
A11: Índice de rentabilidad | B11: =Calculos!$B$50 -> -1.3855333
A12: Punto equilibrio (u./mes) | B12: =Calculos!$B$52 -> 2169.8611 | D12: Control VAN | E12: =IF(ABS(Resumen!$B$8-SUM(Calculos!$B$42:$G$42))<1,"OK","REVISAR") -> OK
D13: Flujo convencional | E13: =IF(AND(Calculos!$B$40<0,Calculos!$G$40>0),"OK","REVISAR TIR") -> REVISAR TIR
A15: Criterios de Ingeniería Económica
A17: • VAN > 0: el proyecto crea valor a la TMAR seleccionada.
A18: • TIR > TMAR: la rentabilidad interna supera el rendimiento mínimo exigido.
A19: • VAN y TIR no se comparan entre sí: tienen unidades diferentes.
A20: • El flujo es económico y no incorpora deuda, intereses ni dividendos.
A22: Guía de lectura del modelo
A24: Input editable | B24: Azul sobre amarillo | D24: Fórmula | E24: Negro sobre claro
A25: Vínculo interno | B25: Verde en Fuentes | D25: Alerta | E25: Rojo = alerta

Sheet Inputs
A1: INPUTS Y SUPUESTOS DEL MODELO
A2: Edite sólo las celdas amarillas con fuente azul.
A4: Categoría | B4: Parámetro | C4: Valor | D4: Unidad | E4: Confianza | F4: Fuente | G4: Nota
A5: Modelo | B5: Escenario activo | C5: Base | D5: texto | E5: SUPUESTO | F5: Selección del usuario | G5: Valores permitidos: Pesimista, Base u Optimista.
A6: Modelo | B6: TMAR nominal anual | C6: 0.2046 | D6: % anual nominal | E6: ESTIMADO | F6: https://www.cmfchile.cl/portal/estadisticas/626/w4-article-111825.html | G6: PISO OBSERVADO, no el costo de oportunidad del titular. CMF, Certificado 07/2026 (promedios de junio 2026, vigente desde el 14-07-2026): interés corriente de 20,46% anual para operaciones no reajustables en moneda nacional de 90 días o más entre 200 y 5.000 UF. La inversión inicial de $43.516.722 equivale a 1.065 UF, dentro de ese tramo. El capital propio es subordinado a esa deuda, luego la TMAR correcta es MAYOR. Reemplaza el stub de 15% de la etapa 10, que quedaba por DEBAJO del costo observado de deuda del mismo tamaño. Spread sobre la TPM (4,5%, Banco Central, https://www.bcentral.cl/areas/politica-monetaria): 15,96 puntos. NO se descompone riesgo por riesgo: no existe fuente pública que lo permita para una microempresa de alimentos en Temuco y repartir los puntos con decimales sería inventar. Límite: el interés corriente es un promedio de operaciones heterogéneas, expresado en forma lineal anual base 360 días, no una cotización para esta empresa. La decisión no es sensible a la tasa: el VAN se anula recién en 35,69% (la TIR); VAN@15% $44.017.948, VAN@20,46% $28.308.713. Gestión que lo cerraría: que el titular declare por escrito el retorno de su alternativa real de inversión.
A7: Modelo | B7: Inflación anual | C7: 0.03 | D7: % anual desde año 2 | E7: ESTIMADO | F7: https://www.bcentral.cl/documents/33528/8413153/IPoM%2Bjunio%2B2026.pdf/93388589-0929-4ad6-b166-10981ca34946 | G7: IPoM junio 2026 ubica expectativas a uno y dos años en torno a 3%. Se escala precio y costos simétricamente.
A8: Modelo | B8: Capital máximo disponible | C8: 50000000 | D8: CLP | E8: VERIFICADO | F8: datos/supuestos.json#meta.restriccion_capital_clp | G8: Restricción declarada en el enunciado.
A9: Modelo | B9: Horizonte de evaluación | C9: 5 | D9: años | E9: SUPUESTO | F9: datos/supuestos.json#meta.horizonte_evaluacion_anios | G9: Horizonte fijado en el statement.
A10: Ventas | B10: Precio B2B neto base | C10: 4200 | D10: CLP neto/unidad en pesos base 2026 | E10: SUPUESTO | F10: 02-competencia/index.html | G10: Se usa solo porque el parámetro de etapa 02 está pendiente. Está entre PF retail neto ($3.017) y foodservice publicado ($5.034); no representa disposición a pagar validada.
A11: Ventas | B11: SOM año 1 (0 = usar referencia) | C11: 0 | D11: pizzas/mes | E11: PENDIENTE | F11: datos/supuestos.json#mercado.som_ano1_pizzas_mes | G11: 0 = usar el volumen año 1 de referencia. La etapa 03 lo cierra en terreno.
A12: Ventas | B12: Volumen año 1 (referencia) | C12: 30000 | D12: pizzas/año | E12: SUPUESTO | F12: 01-mercado/index.html | G12: 2.500 unidades/mes. Sustituir por mercado.som_ano1_pizzas_mes × 12 cuando etapa 03 lo valide.
A13: Ventas | B13: Volumen año 2 (referencia) | C13: 42000 | D13: pizzas/año | E13: SUPUESTO | F13: Etapa 10 | G13: Rampa comercial no validada.
A14: Ventas | B14: Volumen año 3 (referencia) | C14: 54000 | D14: pizzas/año | E14: SUPUESTO | F14: Etapa 10 | G14: Rampa comercial no validada.
A15: Ventas | B15: Volumen año 4 (referencia) | C15: 66000 | D15: pizzas/año | E15: SUPUESTO | F15: Etapa 10 | G15: Rampa comercial no validada.
A16: Ventas | B16: Volumen año 5 (referencia) | C16: 72000 | D16: pizzas/año | E16: SUPUESTO | F16: Etapa 10 | G16: Rampa comercial no validada.
A17: Ventas | B17: Rampa año 2 (0 = derivar) | C17: 0 | D17: multiplicador sobre año 1 | E17: PENDIENTE | F17: datos/supuestos.json#comercial.rampa_ano2_factor | G17: 0 = derivar la forma de los volúmenes de referencia. La etapa 11 no publicó factor y no se inventa uno.
... A38: Operación | B38: Arriendo por m²/mes | C38: 6331 | D38: CLP/m²/mes | E38: ESTIMADO | F38: https://chilepropiedades.cl/ver-publicacion/arriendo-mensual/temuco/bodega/bodega-nueva-de-1-500-m2-acceso-norte-de-tco-162267/117714745 ; https://propiedades.bmi.cl/6057 | G38: Punto medio entre avisos industriales de 0,15 y 0,16 UF/m²/mes, convertido con UF base $40.844,79. Son bodegas mayores; no prueba precio de un local alimentario pequeño.
A39: Operación | B39: Arriendo mensual directo (0 = calcular) | C39: 0 | D39: CLP/mes | E39: PENDIENTE | G39: Depende del metraje, gastos comunes y de encontrar un inmueble compatible con uso de suelo y habilitación sanitaria.
A40: Operación | B40: Nómina bruta mensual | C40: 1100000 | D40: CLP/mes, suma de sueldos brutos imponibles de trabajadores dependientes | E40: ESTIMADO | F40: https://www.ine.gob.cl/estadisticas-por-tema/mercado-laboral/encuesta-suplementaria-de-ingresos ; https://fcje.ufro.cl/noticias/la-araucania-frente-a-la-esi-2025-desafios-para-un-desarrollo-con-mejores-ingresos/ ; datos/supuestos.json#macro.ingreso_minimo_mensual_clp | G40: RÉGIMEN, desde el mes 4. Dotación dependiente: 1 operario de producción a jornada completa 42 h ($700.000 bruto) + 1 operario polivalente a jornada parcial 24 h ($400.000 bruto). Cada bruto incluye sueldo base + gratificación art. 50 del Código del Trabajo (25% con tope de 4,75 IMM anuales = $219.115/mes); no volver a sumarla. ESTE VALOR NO INCLUYE EL RETIRO DE LA TITULAR: el modelo debe sumar rrhh.retiro_titular_mensual_clp SIN aplicarle macro.factor_costo_empresa. Si se prefiere una sola línea ya calculada, usar rrhh.costo_personal_mensual_regimen_clp. Los sueldos son ESTIMADOS: no existe serie pública de remuneración por cargo y comuna; se anclaron en el ingreso mínimo legal y en la ESI 2025 convertida de líquido a bruto.
A41: Operación | B41: Factor costo empresa | C41: 1.0853 | D41: multiplicador sobre sueldo bruto imponible de trabajador dependiente | E41: VERIFICADO | F41: https://www.spensiones.cl/portal/institucional/594/w3-propertyvalue-10906.html ; https://www.chileatiende.gob.cl/fichas/130987-aportes-del-empleador-al-sistema-de-pensiones ; https://www.isl.gob.cl/cotizaciones/ ; https://www.isl.gob.cl/wp-content/uploads/2024/08/Clasificador-Actividades-Economicas-2021.pdf ; https://www.previred.com/indicadores-previsionales/ | G41: MULTIPLICADOR DESNUDO, se usa tal cual (1,0853 = 8,53% sobre el bruto). Suma: 3,50% cotización de cargo del empleador Ley 21.735 vigente 08-2026 a 07-2027 (incluye el SIS, que desde agosto 2026 se financia dentro del Seguro Social Previsional y ya no se cotiza aparte) + 2,40% seguro de cesantía AFC contrato indefinido + 0,93% tasa base Ley 16.744 (0,90% básica + 0,03% SANNA) + 1,70% cotización adicional DS 110 para CIIU 107500 'elaboración de comidas y platos preparados envasados, rotulados y con información nutricional'. CONDICIONES: contrato indefinido (a plazo fijo el AFC sube a 3,00% y el factor a 1,0913); empresa nueva sin evaluación de siniestralidad (DS 67 puede subir o bajar la adicional desde el tercer año); rentas muy por debajo del tope imponible de 90 UF, por lo que todas las tasas aplican íntegras. NO APLICA al retiro de la titular por sueldo empresarial (ver rrhh.retiro_titular_mensual_clp). NO incluye provisiones de feriado ni de indemnización: para eso ver rrhh.factor_costo_empresa_con_provisiones. ADVERTENCIA: el stub 1,22 de la etapa 10 sobrestima el desembolso mensual exigible en ~14 puntos porcentuales.
A42: Operación | B42: Servicios fijos mensuales | C42: 180000 | D42: CLP/mes | E42: SUPUESTO | F42: Etapa 10 | G42: Cargo fijo de electricidad, agua, gas, internet y residuos, separado del consumo variable.
A43: Operación | B43: Mantenimiento mensual | C43: 100000 | D43: CLP/mes | E43: SUPUESTO | F43: Etapa 10 | G43: Reserva preventiva; validar con equipos elegidos.
A44: Operación | B44: Administración mensual | C44: 160000 | D44: CLP/mes | E44: SUPUESTO | F44: Etapa 10 | G44: Contabilidad, software básico, telefonía y gastos bancarios.
A45: Operación | B45: Ventas mensuales | C45: 180000 | D45: CLP/mes | E45: SUPUESTO | F45: Etapa 10 | G45: Muestras, visitas y material comercial.
A46: Operación | B46: Seguros mensuales | C46: 60000 | D46: CLP/mes | E46: SUPUESTO | F46: Etapa 10 | G46: Cotización pendiente.
A47: Operación | B47: Días cuentas por cobrar | C47: 30 | D47: días | E47: SUPUESTO | F47: datos/parametros-02-competencia.json#precios.plazo_cobro_dias | G47: Fallback consistente con el modelo de negocio; debe sustituirse por práctica validada.
A48: Operación | B48: Días inventario | C48: 15 | D48: días de costo variable | E48: SUPUESTO | F48: Etapa 10 | G48: Materia prima más producto terminado.
A49: Operación | B49: Días cuentas por pagar | C49: 0 | D49: días de costo variable | E49: SUPUESTO | F49: Etapa 10 | G49: Caso conservador sin crédito de proveedores.
A50: Operación | B50: Costo de personal mensual (0 = calcular) | C50: 2393830 | D50: CLP/mes | E50: ESTIMADO | F50: 09-rrhh/index.html | G50: DERIVADO, no es un dato independiente: 1.100.000 × 1,0853 + 1.200.000. Existe sólo para evitar que el retiro de la titular se pierda si el modelo cablea una sola línea de personal. Si se usa esta clave, NO multiplicar de nuevo por macro.factor_costo_empresa. Compara contra el stub de E10 (2.200.000 × 1,22 = 2.684.000): $290.170/mes menos, $3.482.040 al año.
A51: Operación | B51: Capacidad instalada (un/día, 0 = sin tope) | C51: 60 | D51: unidades/día (SKU familiar 30 cm) | E51: ESTIMADO | F51: https://calvac.cl/venta/abatidor-10-bandejas-2/ + https://www.supermaq.cl/abatidor/abatidor_congelador_5_bandejas.pdf | G51: Cuello de botella GEOMÉTRICO, no térmico. Bandeja de 610x410 mm: floor(610/300) x floor(410/300) = 2 discos de 300 mm por bandeja; 10 bandejas = 20 pizzas/ciclo = 8,5 kg, el 28% de los 30 kg declarados. Con ciclo de 240 min: 2 ciclos en jornada de 8,4 h más 1 ciclo desatendido que el equipo almacena solo al terminar = 3 ciclos/día x 20 = 60. Techo absoluto con operación 24 h: 6 ciclos = 120/día. El horno pizzero de 2 cámaras 40x40 (~24 pizzas/h) y la amasadora de 20 kg (83 bollos de 240 g) NO son limitantes. En SKU individual de 200 mm: 3x2 = 6 por bandeja = 60/ciclo = 180/día.
... A88: Escenarios | B88: Sensibilidad: volumen alto | C88: 1 | D88: multiplicador | E88: PENDIENTE | F88: datos/supuestos.json#escenarios.volumen_optimista_factor | G88: SIN ANCLA — eje neutro mientras la etapa 12 no publique banda.

Sheet Inversion
A1: INVERSIÓN INICIAL
A2: Escenario activo · montos desde Inputs y fórmulas.
A4: Concepto | B4: Monto | C4: Tratamiento | D4: Referencia
A5: Equipos principales | B5: =Calculos!$B$11 -> 10120237 | C5: Depreciable | D5: Inputs / Calculos
A6: Flete e instalación | B6: =Calculos!$B$12 -> 1518035.6 | C6: Depreciable | D6: Inputs / Calculos
A7: Habilitación + contingencia | B7: =Calculos!$B$16-Calculos!$B$11-Calculos!$B$12 -> 15545741 | C7: Depreciable | D7: Inputs / Calculos
A8: Trámites y preoperación | B8: =Calculos!$B$17-Calculos!$B$16 -> 2500000 | C8: No depreciable en este modelo | D8: Inputs / Calculos
A9: Garantía de arriendo | B9: =Calculos!$B$20 -> 1519440 | C9: Recuperable al año 5 | D9: Inputs / Calculos
A10: Capital de trabajo inicial | B10: =Calculos!$C$37 -> 7263576.7 | C10: Recuperable al año 5 | D10: Inputs / Calculos
A12: INVERSIÓN INICIAL TOTAL | B12: =Calculos!$B$46 -> 38467030

Sheet Flujo_Caja
A1: FLUJO DE CAJA LIBRE DEL PROYECTO
A2: Escenario de Inputs · CLP nominales · sin financiamiento.
A4: Concepto | B4: Año 0 | C4: Año 1 | D4: Año 2 | E4: Año 3 | F4: Año 4 | G4: Año 5
A5: Volumen | B5: =Calculos!$B$23 -> 0 | C5: =Calculos!$C$23 -> 15840 | D5: =Calculos!$D$23 -> 15840 | E5: =Calculos!$E$23 -> 15840 | F5: =Calculos!$F$23 -> 15840 | G5: =Calculos!$G$23 -> 15840
A6: Precio | B6: =Calculos!$B$25 -> 0 | C6: =Calculos!$C$25 -> 4326 | D6: =Calculos!$D$25 -> 4455.78 | E6: =Calculos!$E$25 -> 4589.4534 | F6: =Calculos!$F$25 -> 4727.137 | G6: =Calculos!$G$25 -> 4868.9511
A7: Ingresos | B7: =Calculos!$B$27 -> 0 | C7: =Calculos!$C$27 -> 68523840 | D7: =Calculos!$D$27 -> 70579555 | E7: =Calculos!$E$27 -> 72696942 | F7: =Calculos!$F$27 -> 74877850 | G7: =Calculos!$G$27 -> 77124186
A8: Costos variables | B8: =Calculos!$B$28 -> 0 | C8: =Calculos!$C$28 -> 39699352 | D8: =Calculos!$D$28 -> 40890333 | E8: =Calculos!$E$28 -> 42117042 | F8: =Calculos!$F$28 -> 43380554 | G8: =Calculos!$G$28 -> 44681970
A9: Costos fijos | B9: =Calculos!$B$29 -> 0 | C9: =Calculos!$C$29 -> 47382678 | D9: =Calculos!$D$29 -> 48804158 | E9: =Calculos!$E$29 -> 50268283 | F9: =Calculos!$F$29 -> 51776332 | G9: =Calculos!$G$29 -> 53329622
A10: EBITDA | B10: =Calculos!$B$30 -> 0 | C10: =Calculos!$C$30 -> -18558190 | D10: =Calculos!$D$30 -> -19114936 | E10: =Calculos!$E$30 -> -19688384 | F10: =Calculos!$F$30 -> -20279035 | G10: =Calculos!$G$30 -> -20887406
A11: Depreciación | B11: =Calculos!$B$31 -> 0 | C11: =Calculos!$C$31 -> 2718401.3 | D11: =Calculos!$D$31 -> 2718401.3 | E11: =Calculos!$E$31 -> 2718401.3 | F11: =Calculos!$F$31 -> 2718401.3 | G11: =Calculos!$G$31 -> 2718401.3
A12: EBIT | B12: =Calculos!$B$32 -> 0 | C12: =Calculos!$C$32 -> -21276591 | D12: =Calculos!$D$32 -> -21833337 | E12: =Calculos!$E$32 -> -22406785 | F12: =Calculos!$F$32 -> -22997437 | G12: =Calculos!$G$32 -> -23605808
A13: Pérdida tributaria inicial | B13: =Calculos!$B$33 -> 0 | C13: =Calculos!$C$33 -> 0 | D13: =Calculos!$D$33 -> 21276591 | E13: =Calculos!$E$33 -> 43109928 | F13: =Calculos!$F$33 -> 65516713 | G13: =Calculos!$G$33 -> 88514150
A14: Renta imponible | B14: =Calculos!$B$34 -> 0 | C14: =Calculos!$C$34 -> 0 | D14: =Calculos!$D$34 -> 0 | E14: =Calculos!$E$34 -> 0 | F14: =Calculos!$F$34 -> 0 | G14: =Calculos!$G$34 -> 0
A15: Impuesto | B15: =Calculos!$B$35 -> 0 | C15: =Calculos!$C$35 -> 0 | D15: =Calculos!$D$35 -> 0 | E15: =Calculos!$E$35 -> 0 | F15: =Calculos!$F$35 -> 0 | G15: =Calculos!$G$35 -> 0
A16: Pérdida tributaria final | B16: =Calculos!$B$36 -> 0 | C16: =Calculos!$C$36 -> 21276591 | D16: =Calculos!$D$36 -> 43109928 | E16: =Calculos!$E$36 -> 65516713 | F16: =Calculos!$F$36 -> 88514150 | G16: =Calculos!$G$36 -> 1.1211996e+08
A17: Capital de trabajo | B17: =Calculos!$B$37 -> 0 | C17: =Calculos!$C$37 -> 7263576.7 | D17: =Calculos!$D$37 -> 7481484 | E17: =Calculos!$E$37 -> 7705928.5 | F17: =Calculos!$F$37 -> 7937106.3 | G17: =Calculos!$G$37 -> 8175219.5
A18: Variación capital de trabajo | B18: =Calculos!$B$38 -> 0 | C18: =Calculos!$C$38 -> 0 | D18: =Calculos!$D$38 -> 217907.3 | E18: =Calculos!$E$38 -> 224444.52 | F18: =Calculos!$F$38 -> 231177.85 | G18: =Calculos!$G$38 -> 238113.19
A19: Recuperaciones terminales | B19: =Calculos!$B$39 -> 0 | C19: =Calculos!$C$39 -> 0 | D19: =Calculos!$D$39 -> 0 | E19: =Calculos!$E$39 -> 0 | F19: =Calculos!$F$39 -> 0 | G19: =Calculos!$G$39 -> 12413061
A20: Flujo libre | B20: =Calculos!$B$40 -> -38467030 | C20: =Calculos!$C$40 -> -18558190 | D20: =Calculos!$D$40 -> -19332843 | E20: =Calculos!$E$40 -> -19912828 | F20: =Calculos!$F$40 -> -20510213 | G20: =Calculos!$G$40 -> -8712458.6
A21: Factor descuento | B21: =Calculos!$B$41 -> 1 | C21: =Calculos!$C$41 -> 0.83015109 | D21: =Calculos!$D$41 -> 0.68915083 | E21: =Calculos!$E$41 -> 0.57209931 | F21: =Calculos!$F$41 -> 0.47492886 | G21: =Calculos!$G$41 -> 0.39426271
A22: Flujo descontado | B22: =Calculos!$B$42 -> -38467030 | C22: =Calculos!$C$42 -> -15406102 | D22: =Calculos!$D$42 -> -13323245 | E22: =Calculos!$E$42 -> -11392115 | F22: =Calculos!$F$42 -> -9740892.2 | G22: =Calculos!$G$42 -> -3434997.6
A23: Flujo acumulado | B23: =Calculos!$B$43 -> -38467030 | C23: =Calculos!$C$43 -> -57025220 | D23: =Calculos!$D$43 -> -76358063 | E23: =Calculos!$E$43 -> -96270891 | F23: =Calculos!$F$43 -> -1.167811e+08 | G23: =Calculos!$G$43 -> -1.2549356e+08
A24: Flujo descontado acumulado | B24: =Calculos!$B$44 -> -38467030 | C24: =Calculos!$C$44 -> -53873132 | D24: =Calculos!$D$44 -> -67196376 | E24: =Calculos!$E$44 -> -78588492 | F24: =Calculos!$F$44 -> -88329384 | G24: =Calculos!$G$44 -> -91764381

Sheet Escenarios
A1: ESCENARIOS
A2: Cada caso recalcula impuestos, capital de trabajo y valor terminal.
A4: Escenario | B4: VAN | C4: TIR | D4: Inversión inicial | E4: Fondeo máximo | F4: Payback descontado | G4: Punto equilibrio/mes
A5: Pesimista | B5: =Calculos!$B$102 -> -1.5902962e+08 | C5: =Calculos!$B$103 -> #N/A | D5: =Calculos!$B$101 -> 45795247 | E5: =Calculos!$B$106 -> 2.3544791e+08 | F5: =Calculos!$B$104 -> #N/A | G5: =Calculos!$B$107 -> 6489.5569
A6: Base | B6: =Calculos!$B$157 -> -91764381 | C6: =Calculos!$B$158 -> #N/A | D6: =Calculos!$B$156 -> 38467030 | E6: =Calculos!$B$161 -> 1.2549356e+08 | F6: =Calculos!$B$159 -> #N/A | G6: =Calculos!$B$162 -> 2169.8611
A7: Optimista | B7: =Calculos!$B$212 -> -44126530 | C7: =Calculos!$B$213 -> #N/A | D7: =Calculos!$B$211 -> 33656647 | E7: =Calculos!$B$216 -> 54739533 | F7: =Calculos!$B$214 -> #N/A | G7: =Calculos!$B$217 -> 1470.6379

Sheet Sensibilidad
A1: SENSIBILIDAD DEL VAN
A2: Filas: cambio de volumen · columnas: cambio de precio · costos y CAPEX en caso base.
A4: Volumen \ Precio | B4: =(Inputs!$C$85)-1 -> -0.28 | C4: =(1)-1 -> 0 | D4: =(Inputs!$C$86)-1 -> 0.2
A5: =(Inputs!$C$87)-1 -> 0 | B5: =Calculos!$B$267 -> -1.5044594e+08 | C5: =Calculos!$B$322 -> -91764381 | D5: =Calculos!$B$377 -> -49848980
A6: =(1)-1 -> 0 | B6: =Calculos!$B$432 -> -1.5044594e+08 | C6: =Calculos!$B$487 -> -91764381 | D6: =Calculos!$B$542 -> -49848980
A7: =(Inputs!$C$88)-1 -> 0 | B7: =Calculos!$B$597 -> -1.5044594e+08 | C7: =Calculos!$B$652 -> -91764381 | D7: =Calculos!$B$707 -> -49848980

Sheet Fuentes
A1: TRAZABILIDAD Y FUENTES
A2: Copia documental de Inputs; los cambios se realizan en Inputs.
A4: Parámetro | B4: Valor actual | C4: Unidad | D4: Confianza | E4: Fuente | F4: Nota
A5: =Inputs!$B$6 -> TMAR nominal anual | B5: =Inputs!$C$6 -> 0.2046 | C5: =Inputs!$D$6 -> % anual nominal | D5: =Inputs!$E$6 -> ESTIMADO | E5: =Inputs!$F$6 -> https://www.cmfchile.cl/portal/estadisticas/626/w4-article-111825.html | F5: =Inputs!$G$6 -> PISO OBSERVADO, no el costo de oportunidad del titular. CMF, Certificado 07/2026 (promedios de junio 2026, vigente desde el 14-07-2026): interés corriente de 20,46% anual para operaciones no reajustables en moneda nacional de 90 días o más entre 200 y 5.000 UF. La inversión inicial de $43.516.722 equivale a 1.065 UF, dentro de ese tramo. El capital propio es subordinado a esa deuda, luego la TMAR correcta es MAYOR. Reemplaza el stub de 15% de la etapa 10, que quedaba por DEBAJO del costo observado de deuda del mismo tamaño. Spread sobre la TPM (4,5%, Banco Central, https://www.bcentral.cl/areas/politica-monetaria): 15,96 puntos. NO se descompone riesgo por riesgo: no existe fuente pública que lo permita para una microempresa de alimentos en Temuco y repartir los puntos con decimales sería inventar. Límite: el interés corriente es un promedio de operaciones heterogéneas, expresado en forma lineal anual base 360 días, no una cotización para esta empresa. La decisión no es sensible a la tasa: el VAN se anula recién en 35,69% (la TIR); VAN@15% $44.017.948, VAN@20,46% $28.308.713. Gestión que lo cerraría: que el titular declare por escrito el retorno de su alternativa real de inversión.
A6: =Inputs!$B$7 -> Inflación anual | B6: =Inputs!$C$7 -> 0.03 | C6: =Inputs!$D$7 -> % anual desde año 2 | D6: =Inputs!$E$7 -> ESTIMADO | E6: =Inputs!$F$7 -> https://www.bcentral.cl/documents/33528/8413153/IPoM%2Bjunio%2B2026.pdf/93388589-0929-4ad6-b166-10981ca34946 | F6: =Inputs!$G$7 -> IPoM junio 2026 ubica expectativas a uno y dos años en torno a 3%. Se escala precio y costos simétricamente.
A7: =Inputs!$B$8 -> Capital máximo disponible | B7: =Inputs!$C$8 -> 50000000 | C7: =Inputs!$D$8 -> CLP | D7: =Inputs!$E$8 -> VERIFICADO | E7: =Inputs!$F$8 -> datos/supuestos.json#meta.restriccion_capital_clp | F7: =Inputs!$G$8 -> Restricción declarada en el enunciado.
A8: =Inputs!$B$9 -> Horizonte de evaluación | B8: =Inputs!$C$9 -> 5 | C8: =Inputs!$D$9 -> años | D8: =Inputs!$E$9 -> SUPUESTO | E8: =Inputs!$F$9 -> datos/supuestos.json#meta.horizonte_evaluacion_anios | F8: =Inputs!$G$9 -> Horizonte fijado en el statement.
A9: =Inputs!$B$10 -> Precio B2B neto base | B9: =Inputs!$C$10 -> 4200 | C9: =Inputs!$D$10 -> CLP neto/unidad en pesos base 2026 | D9: =Inputs!$E$10 -> SUPUESTO | E9: =Inputs!$F$10 -> 02-competencia/index.html | F9: =Inputs!$G$10 -> Se usa solo porque el parámetro de etapa 02 está pendiente. Está entre PF retail neto ($3.017) y foodservice publicado ($5.034); no representa disposición a pagar validada.
A10: =Inputs!$B$11 -> SOM año 1 (0 = usar referencia) | B10: =Inputs!$C$11 -> 0 | C10: =Inputs!$D$11 -> pizzas/mes | D10: =Inputs!$E$11 -> PENDIENTE | E10: =Inputs!$F$11 -> datos/supuestos.json#mercado.som_ano1_pizzas_mes | F10: =Inputs!$G$11 -> 0 = usar el volumen año 1 de referencia. La etapa 03 lo cierra en terreno.
A11: =Inputs!$B$12 -> Volumen año 1 (referencia) | B11: =Inputs!$C$12 -> 30000 | C11: =Inputs!$D$12 -> pizzas/año | D11: =Inputs!$E$12 -> SUPUESTO | E11: =Inputs!$F$12 -> 01-mercado/index.html | F11: =Inputs!$G$12 -> 2.500 unidades/mes. Sustituir por mercado.som_ano1_pizzas_mes × 12 cuando etapa 03 lo valide.
A12: =Inputs!$B$13 -> Volumen año 2 (referencia) | B12: =Inputs!$C$13 -> 42000 | C12: =Inputs!$D$13 -> pizzas/año | D12: =Inputs!$E$13 -> SUPUESTO | E12: =Inputs!$F$13 -> Etapa 10 | F12: =Inputs!$G$13 -> Rampa comercial no validada.
A13: =Inputs!$B$14 -> Volumen año 3 (referencia) | B13: =Inputs!$C$14 -> 54000 | C13: =Inputs!$D$14 -> pizzas/año | D13: =Inputs!$E$14 -> SUPUESTO | E13: =Inputs!$F$14 -> Etapa 10 | F13: =Inputs!$G$14 -> Rampa comercial no validada.
A14: =Inputs!$B$15 -> Volumen año 4 (referencia) | B14: =Inputs!$C$15 -> 66000 | C14: =Inputs!$D$15 -> pizzas/año | D14: =Inputs!$E$15 -> SUPUESTO | E14: =Inputs!$F$15 -> Etapa 10 | F14: =Inputs!$G$15 -> Rampa comercial no validada.
A15: =Inputs!$B$16 -> Volumen año 5 (referencia) | B15: =Inputs!$C$16 -> 72000 | C15: =Inputs!$D$16 -> pizzas/año | D15: =Inputs!$E$16 -> SUPUESTO | E15: =Inputs!$F$16 -> Etapa 10 | F15: =Inputs!$G$16 -> Rampa comercial no validada.
A16: =Inputs!$B$17 -> Rampa año 2 (0 = derivar) | B16: =Inputs!$C$17 -> 0 | C16: =Inputs!$D$17 -> multiplicador sobre año 1 | D16: =Inputs!$E$17 -> PENDIENTE | E16: =Inputs!$F$17 -> datos/supuestos.json#comercial.rampa_ano2_factor | F16: =Inputs!$G$17 -> 0 = derivar la forma de los volúmenes de referencia. La etapa 11 no publicó factor y no se inventa uno.
A17: =Inputs!$B$18 -> Rampa año 3 (0 = derivar) | B17: =Inputs!$C$18 -> 0 | C17: =Inputs!$D$18 -> multiplicador sobre año 1 | D17: =Inputs!$E$18 -> PENDIENTE | E17: =Inputs!$F$18 -> datos/supuestos.json#comercial.rampa_ano3_factor | F17: =Inputs!$G$18 -> 0 = derivar la forma de los volúmenes de referencia. La etapa 11 no publicó factor y no se inventa uno.
A18: =Inputs!$B$19 -> Rampa año 4 (0 = derivar) | B18: =Inputs!$C$19 -> 0 | C18: =Inputs!$D$19 -> multiplicador sobre año 1 | D18: =Inputs!$E$19 -> PENDIENTE | E18: =Inputs!$F$19 -> datos/supuestos.json#comercial.rampa_ano4_factor | F18: =Inputs!$G$19 -> 0 = derivar la forma de los volúmenes de referencia. La etapa 11 no publicó factor y no se inventa uno.
A19: =Inputs!$B$20 -> Rampa año 5 (0 = derivar) | B19: =Inputs!$C$20 -> 0 | C19: =Inputs!$D$20 -> multiplicador sobre año 1 | D19: =Inputs!$E$20 -> PENDIENTE | E19: =Inputs!$F$20 -> datos/supuestos.json#comercial.rampa_ano5_factor | F19: =Inputs!$G$20 -> 0 = derivar la forma de los volúmenes de referencia. La etapa 11 no publicó factor y no se inventa uno.
A20: =Inputs!$B$21 -> Impuesto año 1 | B20: =Inputs!$C$21 -> 0.125 | C20: =Inputs!$D$21 -> % IDPC Pro Pyme año comercial 2027 | D20: =Inputs!$E$21 -> VERIFICADO | E20: =Inputs!$F$21 -> https://www.sii.cl/normativa_legislacion/circulares/2025/circu53.pdf | F20: =Inputs!$G$21 -> Aplica si la empresa califica al régimen Pro Pyme General del art. 14 D N°3.
A21: =Inputs!$B$22 -> Impuesto año 2 | B21: =Inputs!$C$22 -> 0.125 | C21: =Inputs!$D$22 -> % IDPC Pro Pyme año comercial 2028 | D21: =Inputs!$E$22 -> VERIFICADO | E21: =Inputs!$F$22 -> https://www.sii.cl/preguntas_frecuentes/declaracion_renta/001_140_4708.htm | F21: =Inputs!$G$22 -> Año comercial 2027. La tabla de tasas IDPC del SII muestra 12,5% para los años comerciales 2025, 2026 y 2027 bajo el art. 14 D N°3 (rebaja de la Ley 21.755, art. vigésimo quinto). Corrige el 15% anterior, que adelantaba un año la escala.
A22: =Inputs!$B$23 -> Impuesto año 3 | B22: =Inputs!$C$23 -> 0.15 | C22: =Inputs!$D$23 -> % IDPC permanente | D22: =Inputs!$E$23 -> ESTIMADO | E22: =Inputs!$F$23 -> https://www.sii.cl/preguntas_frecuentes/declaracion_renta/001_140_4708.htm | F22: =Inputs!$G$23 -> Año comercial 2028. Corrige el 25% anterior, que contradecía su propia nota: ésta decía que el 25% rige desde 2029, pero se aplicaba al año 3, que es 2028.
A23: =Inputs!$B$24 -> Impuesto año 4 | B23: =Inputs!$C$24 -> 0.25 | C23: =Inputs!$D$24 -> % IDPC permanente | D23: =Inputs!$E$24 -> ESTIMADO | E23: =Inputs!$F$24 -> https://www.sii.cl/preguntas_frecuentes/declaracion_renta/001_140_4708.htm | F23: =Inputs!$G$24 -> Año comercial 2029: tasa permanente del régimen. Supone permanencia normativa.
A24: =Inputs!$B$25 -> Impuesto año 5 | B24: =Inputs!$C$25 -> 0.25 | C24: =Inputs!$D$25 -> % IDPC permanente | D24: =Inputs!$E$25 -> ESTIMADO | E24: =Inputs!$F$25 -> https://www.sii.cl/preguntas_frecuentes/declaracion_renta/001_140_4708.htm | F24: =Inputs!$G$25 -> Año comercial 2030: tasa permanente del régimen. Supone permanencia normativa.
A25: =Inputs!$B$26 -> Harina por pizza | B25: =Inputs!$C$26 -> 0.151 | C25: =Inputs!$D$26 -> kg/pizza familiar 30 cm | D25: =Inputs!$E$26 -> ESTIMADO | E25: =Inputs!$F$26 -> https://eur-lex.europa.eu/legal-content/ES/TXT/HTML/?uri=CELEX:32010R0097 | F25: =Inputs!$G$26 -> Reglamento (UE) 97/2010, pliego Pizza Napoletana ETG: harina 1.800 g : agua 1 L : sal 50-55 g : levadura 3 g, total 2.855 g, de donde la harina es el 63,0% de la masa. Bollo de 240 g (techo del rango ETG 180-250 g) x 0,630 = 151 g. Se toma el techo porque un disco precocido congelado debe resistir manipulación, apilado en caja de 12 y transporte: densidad 0,34 g/cm² sobre 300 mm, más gruesa que una napoletana. Sustituye el supuesto de 0,2 kg de etapa 10, que era 32% mayor.
A26: =Inputs!$B$27 -> Salsa por pizza | B26: =Inputs!$C$27 -> 0.08 | C26: =Inputs!$D$27 -> kg/pizza familiar 30 cm | D26: =Inputs!$E$27 -> ESTIMADO | E26: =Inputs!$F$27 -> https://eur-lex.europa.eu/legal-content/ES/TXT/HTML/?uri=CELEX:32010R0097 | F26: =Inputs!$G$27 -> Pliego ETG para la Margherita: 'entre 60 y 80 g de tomates pelados triturados'. Se toma el techo. CUADRA CON EL PRECIO DE 06: la salsa es tomate pelado triturado en crudo con sal y aceite, sin reducción, así que 1 kg de insumo ≈ 1 kg de salsa y el gramaje se valoriza directamente con datos/parametros-06-insumos.json#insumos.salsa_tomate_clp_kg. Si se decide cocer y reducir la salsa, este número sube por pérdida de agua.
A27: =Inputs!$B$28 -> Mozzarella por pizza | B27: =Inputs!$C$28 -> 0.1 | C27: =Inputs!$D$28 -> kg/pizza familiar 30 cm | D27: =Inputs!$E$28 -> ESTIMADO | E27: =Inputs!$F$28 -> https://eur-lex.europa.eu/legal-content/ES/TXT/HTML/?uri=CELEX:32010R0097 | F27: =Inputs!$G$28 -> LÍNEA MÁS SENSIBLE DEL MODELO. Dos anclas independientes convergen: (a) pliego ETG Margherita, 'entre 80 y 100 g' de mozzarella; (b) ficha técnica comercial de minipizza congelada que declara mozzarella 20,5% en masa, que sobre 426 g da 89 g. Se toma 100 g, techo del rango ETG, porque sobre 300 mm da mayor densidad superficial que 100 g sobre los 350 mm que el ETG permite, y porque la carga de queso visible es el atributo que el canal compra. Sustituye el supuesto de 0,12 kg de etapa 10: a $8.403,36/kg el costo de queso baja de $1.008 a $840 por unidad. NINGUNA de las dos anclas es chilena ni foodservice, y el rendimiento al fundir no está probado: cerrar con panel de degustación en etapa 03 y con el piloto.
A28: =Inputs!$B$29 -> Otros ingredientes por pizza | B28: =Inputs!$C$29 -> 550 | C28: =Inputs!$D$29 -> CLP neto/pizza | D28: =Inputs!$E$29 -> SUPUESTO | E28: =Inputs!$F$29 -> Etapa 10 | F28: =Inputs!$G$29 -> Aceite, levadura, sal, especias y topping; pendiente de receta y cotización.
A29: =Inputs!$B$30 -> Envase por pizza | B29: =Inputs!$C$30 -> 300 | C29: =Inputs!$D$30 -> CLP neto/pizza | D29: =Inputs!$E$30 -> SUPUESTO | E29: =Inputs!$F$30 -> 06-insumos/index.html | F29: =Inputs!$G$30 -> Fallback hasta que etapa 06 cierre film, etiqueta y caja máster.
A30: =Inputs!$B$31 -> Energía variable por pizza | B30: =Inputs!$C$31 -> 120 | C30: =Inputs!$D$31 -> CLP/pizza | D30: =Inputs!$E$31 -> SUPUESTO | E30: =Inputs!$F$31 -> https://calvac.cl/venta/abatidor-10-bandejas-2/ | F30: =Inputs!$G$31 -> Bolsa de costo para horno, abatimiento y congelación. Debe reemplazarse por balance kWh/ciclo y tarifa contratada.
A31: =Inputs!$B$32 -> Distribución variable por pizza | B31: =Inputs!$C$32 -> 220 | C31: =Inputs!$D$32 -> CLP/pizza | D31: =Inputs!$E$32 -> SUPUESTO | E31: =Inputs!$F$32 -> Etapa 10 | F31: =Inputs!$G$32 -> Despacho consolidado local sin vehículo propio; cotizar por ruta.
A32: =Inputs!$B$33 -> Merma de ingredientes | B32: =Inputs!$C$33 -> 0.05 | C32: =Inputs!$D$33 -> % | D32: =Inputs!$E$33 -> SUPUESTO | E32: =Inputs!$F$33 -> datos/parametros-10-financiero.json#producto.merma_pct | F32: =Inputs!$G$33 -> PUNTOS PORCENTUALES: 5 = 5%. modelo.js lo divide por 100. NO EXISTE fuente pública chilena de merma de proceso para esta línea; se mantiene el marcador heredado de etapa 10 en vez de inventar precisión. Componentes esperados: recorte de masa al formar, residuo de dosificado de salsa y queso, y producto no conforme de arranque (el dominante). Solo lo cierra un piloto de 3 lotes con pesaje de entrada y salida.
A33: =Inputs!$B$34 -> Precio harina/kg | B33: =Inputs!$C$34 -> 840 | C33: =Inputs!$D$34 -> CLP neto/kg | D33: =Inputs!$E$34 -> VERIFICADO | E33: =Inputs!$F$34 -> https://metafood.cl/REV10100_Harina_Pizza | F33: =Inputs!$G$34 -> Saco de harina para pizza 25 kg publicado a $21.000 + IVA. Falta confirmar flete y disponibilidad en Temuco.
A34: =Inputs!$B$35 -> Precio tomate/kg | B34: =Inputs!$C$35 -> 2383.8 | C34: =Inputs!$D$35 -> CLP neto/kg | D34: =Inputs!$E$35 -> VERIFICADO | E34: =Inputs!$F$35 -> https://metafood.cl/REV10130_Tomate_Pelado_Lata_Bolsa | F34: =Inputs!$G$35 -> Tomate pelado bolsa 5 kg a $11.919 + IVA. Es insumo para formular salsa, no salsa terminada; falta flete a Temuco.
A35: =Inputs!$B$36 -> Precio mozzarella/kg | B35: =Inputs!$C$36 -> 8403.36 | C35: =Inputs!$D$36 -> CLP neto/kg | D35: =Inputs!$E$36 -> ESTIMADO | E35: =Inputs!$F$36 -> https://www.mercadolibre.cl/queso-mozzarella-barra-35-kg-aprox-molfino-argentino/up/MLCU67695246 | F35: =Inputs!$G$36 -> Publicación de vendedor de Temuco a $10.000/kg IVA incluido, con factura y reparto refrigerado; normalizado /1,19. No es cotización por volumen ni demuestra suministro estable.
A36: =Inputs!$B$37 -> Superficie | B36: =Inputs!$C$37 -> 120 | C36: =Inputs!$D$37 -> m² | D36: =Inputs!$E$37 -> SUPUESTO | E36: =Inputs!$F$37 -> 07-local-habilitacion/index.html | F36: =Inputs!$G$37 -> Fallback hasta layout de etapa 04.
A37: =Inputs!$B$38 -> Arriendo por m²/mes | B37: =Inputs!$C$38 -> 6331 | C37: =Inputs!$D$38 -> CLP/m²/mes | D37: =Inputs!$E$38 -> ESTIMADO | E37: =Inputs!$F$38 -> https://chilepropiedades.cl/ver-publicacion/arriendo-mensual/temuco/bodega/bodega-nueva-de-1-500-m2-acceso-norte-de-tco-162267/117714745 ; https://propiedades.bmi.cl/6057 | F37: =Inputs!$G$38 -> Punto medio entre avisos industriales de 0,15 y 0,16 UF/m²/mes, convertido con UF base $40.844,79. Son bodegas mayores; no prueba precio de un local alimentario pequeño.
A38: =Inputs!$B$39 -> Arriendo mensual directo (0 = calcular) | B38: =Inputs!$C$39 -> 0 | C38: =Inputs!$D$39 -> CLP/mes | D38: =Inputs!$E$39 -> PENDIENTE | E38: =Inputs!$F$39 -> 0 | F38: =Inputs!$G$39 -> Depende del metraje, gastos comunes y de encontrar un inmueble compatible con uso de suelo y habilitación sanitaria.
A39: =Inputs!$B$40 -> Nómina bruta mensual | B39: =Inputs!$C$40 -> 1100000 | C39: =Inputs!$D$40 -> CLP/mes, suma de sueldos brutos imponibles de trabajadores dependientes | D39: =Inputs!$E$40 -> ESTIMADO | E39: =Inputs!$F$40 -> https://www.ine.gob.cl/estadisticas-por-tema/mercado-laboral/encuesta-suplementaria-de-ingresos ; https://fcje.ufro.cl/noticias/la-araucania-frente-a-la-esi-2025-desafios-para-un-desarrollo-con-mejores-ingresos/ ; datos/supuestos.json#macro.ingreso_minimo_mensual_clp | F39: =Inputs!$G$40 -> RÉGIMEN, desde el mes 4. Dotación dependiente: 1 operario de producción a jornada completa 42 h ($700.000 bruto) + 1 operario polivalente a jornada parcial 24 h ($400.000 bruto). Cada bruto incluye sueldo base + gratificación art. 50 del Código del Trabajo (25% con tope de 4,75 IMM anuales = $219.115/mes); no volver a sumarla. ESTE VALOR NO INCLUYE EL RETIRO DE LA TITULAR: el modelo debe sumar rrhh.retiro_titular_mensual_clp SIN aplicarle macro.factor_costo_empresa. Si se prefiere una sola línea ya calculada, usar rrhh.costo_personal_mensual_regimen_clp. Los sueldos son ESTIMADOS: no existe serie pública de remuneración por cargo y comuna; se anclaron en el ingreso mínimo legal y en la ESI 2025 convertida de líquido a bruto.
A40: =Inputs!$B$41 -> Factor costo empresa | B40: =Inputs!$C$41 -> 1.0853 | C40: =Inputs!$D$41 -> multiplicador sobre sueldo bruto imponible de trabajador dependiente | D40: =Inputs!$E$41 -> VERIFICADO | E40: =Inputs!$F$41 -> https://www.spensiones.cl/portal/institucional/594/w3-propertyvalue-10906.html ; https://www.chileatiende.gob.cl/fichas/130987-aportes-del-empleador-al-sistema-de-pensiones ; https://www.isl.gob.cl/cotizaciones/ ; https://www.isl.gob.cl/wp-content/uploads/2024/08/Clasificador-Actividades-Economicas-2021.pdf ; https://www.previred.com/indicadores-previsionales/ | F40: =Inputs!$G$41 -> MULTIPLICADOR DESNUDO, se usa tal cual (1,0853 = 8,53% sobre el bruto). Suma: 3,50% cotización de cargo del empleador Ley 21.735 vigente 08-2026 a 07-2027 (incluye el SIS, que desde agosto 2026 se financia dentro del Seguro Social Previsional y ya no se cotiza aparte) + 2,40% seguro de cesantía AFC contrato indefinido + 0,93% tasa base Ley 16.744 (0,90% básica + 0,03% SANNA) + 1,70% cotización adicional DS 110 para CIIU 107500 'elaboración de comidas y platos preparados envasados, rotulados y con información nutricional'. CONDICIONES: contrato indefinido (a plazo fijo el AFC sube a 3,00% y el factor a 1,0913); empresa nueva sin evaluación de siniestralidad (DS 67 puede subir o bajar la adicional desde el tercer año); rentas muy por debajo del tope imponible de 90 UF, por lo que todas las tasas aplican íntegras. NO APLICA al retiro de la titular por sueldo empresarial (ver rrhh.retiro_titular_mensual_clp). NO incluye provisiones de feriado ni de indemnización: para eso ver rrhh.factor_costo_empresa_con_provisiones. ADVERTENCIA: el stub 1,22 de la etapa 10 sobrestima el desembolso mensual exigible en ~14 puntos porcentuales.
A41: =Inputs!$B$42 -> Servicios fijos mensuales | B41: =Inputs!$C$42 -> 180000 | C41: =Inputs!$D$42 -> CLP/mes | D41: =Inputs!$E$42 -> SUPUESTO | E41: =Inputs!$F$42 -> Etapa 10 | F41: =Inputs!$G$42 -> Cargo fijo de electricidad, agua, gas, internet y residuos, separado del consumo variable.
...

Sheet Calculos
A1: MOTOR DE CÁLCULO
A2: Bloques formulados para escenario activo, escenarios comparables y sensibilidad.
A4: Escenario activo
A5: Precio | B5: =IF(Inputs!$C$5="Pesimista",Inputs!$C$70,IF(Inputs!$C$5="Optimista",Inputs!$C$80,Inputs!$C$75)) -> 1
A6: Volumen | B6: =IF(Inputs!$C$5="Pesimista",Inputs!$C$71,IF(Inputs!$C$5="Optimista",Inputs!$C$81,Inputs!$C$76)) -> 1
A7: Costo variable | B7: =IF(Inputs!$C$5="Pesimista",Inputs!$C$72,IF(Inputs!$C$5="Optimista",Inputs!$C$82,Inputs!$C$77)) -> 1
A8: Costo fijo | B8: =IF(Inputs!$C$5="Pesimista",Inputs!$C$73,IF(Inputs!$C$5="Optimista",Inputs!$C$83,Inputs!$C$78)) -> 1
A9: CAPEX | B9: =IF(Inputs!$C$5="Pesimista",Inputs!$C$74,IF(Inputs!$C$5="Optimista",Inputs!$C$84,Inputs!$C$79)) -> 1
A11: Equipos | B11: =IF(Inputs!$C$61>0,Inputs!$C$61,Inputs!$C$53+Inputs!$C$54+Inputs!$C$55+Inputs!$C$56+Inputs!$C$57+Inputs!$C$58+Inputs!$C$59+Inputs!$C$60) -> 10120237
A12: Flete/instalación | B12: =Calculos!$B$11*Inputs!$C$62 -> 1518035.6
A13: Arriendo mensual | B13: =IF(Inputs!$C$39>0,Inputs!$C$39,Inputs!$C$37*Inputs!$C$38) -> 759720
A14: Costo variable unitario base | B14: =((Inputs!$C$26*Inputs!$C$34+Inputs!$C$27*Inputs!$C$35+Inputs!$C$28*Inputs!$C$36+Inputs!$C$29)*(1+Inputs!$C$33)+Inputs!$C$30+Inputs!$C$31+Inputs!$C$32) -> 2433.274
A15: Costo fijo mensual base | B15: =(Calculos!$B$13+IF(Inputs!$C$50>0,Inputs!$C$50,Inputs!$C$40*Inputs!$C$41)+Inputs!$C$42+Inputs!$C$43+Inputs!$C$44+Inputs!$C$45+Inputs!$C$46) -> 3833550
A16: CAPEX depreciable | B16: =(Calculos!$B$11+Calculos!$B$12+Inputs!$C$63)*(1+Inputs!$C$66)*Calculos!$B$9 -> 27184013
A17: CAPEX total | B17: =Calculos!$B$16+(Inputs!$C$64+Inputs!$C$65)*Calculos!$B$9 -> 29684013
A18: Depreciación anual | B18: =Calculos!$B$16/Inputs!$C$68 -> 2718401.3
A19: Valor residual bruto | B19: =Calculos!$B$16*Inputs!$C$69 -> 2718401.3
A20: Garantía arriendo | B20: =Calculos!$B$13*Inputs!$C$67 -> 1519440
A22: Concepto | B22: Año 0 | C22: Año 1 | D22: Año 2 | E22: Año 3 | F22: Año 4 | G22: Año 5
A23: Volumen | C23: =IF(AND(Inputs!$C$51>0,Inputs!$C$52>0),MIN((IF(Inputs!$C$11>0,Inputs!$C$11*12,Inputs!$C$12))*Calculos!$B$6,Inputs!$C$51*Inputs!$C$52*12),(IF(Inputs!$C$11>0,Inputs!$C$11*12,Inputs!$C$12))*Calculos!$B$6) -> 15840 | D23: =IF(AND(Inputs!$C$51>0,Inputs!$C$52>0),MIN((IF(Inputs!$C$11>0,Inputs!$C$11*12,Inputs!$C$12)*IF(Inputs!$C$17>0,Inputs!$C$17,Inputs!$C$13/Inputs!$C$12))*Calculos!$B$6,Inputs!$C$51*Inputs!$C$52*12),(IF(Inputs!$C$11>0,Inputs!$C$11*12,Inputs!$C$12)*IF(Inputs!$C$17>0,Inputs!$C$17,Inputs!$C$13/Inputs!$C$12))*Calculos!$B$6) -> 15840 | E23: =IF(AND(Inputs!$C$51>0,Inputs!$C$52>0),MIN((IF(Inputs!$C$11>0,Inputs!$C$11*12,Inputs!$C$12)*IF(Inputs!$C$18>0,Inputs!$C$18,Inputs!$C$14/Inputs!$C$12))*Calculos!$B$6,Inputs!$C$51*Inputs!$C$52*12),(IF(Inputs!$C$11>0,Inputs!$C$11*12,Inputs!$C$12)*IF(Inputs!$C$18>0,Inputs!$C$18,Inputs!$C$14/Inputs!$C$12))*Calculos!$B$6) -> 15840 | F23: =IF(AND(Inputs!$C$51>0,Inputs!$C$52>0),MIN((IF(Inputs!$C$11>0,Inputs!$C$11*12,Inputs!$C$12)*IF(Inputs!$C$19>0,Inputs!$C$19,Inputs!$C$15/Inputs!$C$12))*Calculos!$B$6,Inputs!$C$51*Inputs!$C$52*12),(IF(Inputs!$C$11>0,Inputs!$C$11*12,Inputs!$C$12)*IF(Inputs!$C$19>0,Inputs!$C$19,Inputs!$C$15/Inputs!$C$12))*Calculos!$B$6) -> 15840 | G23: =IF(AND(Inputs!$C$51>0,Inputs!$C$52>0),MIN((IF(Inputs!$C$11>0,Inputs!$C$11*12,Inputs!$C$12)*IF(Inputs!$C$20>0,Inputs!$C$20,Inputs!$C$16/Inputs!$C$12))*Calculos!$B$6,Inputs!$C$51*Inputs!$C$52*12),(IF(Inputs!$C$11>0,Inputs!$C$11*12,Inputs!$C$12)*IF(Inputs!$C$20>0,Inputs!$C$20,Inputs!$C$16/Inputs!$C$12))*Calculos!$B$6) -> 15840
A24: Escalador | C24: =(1+Inputs!$C$7)^1 -> 1.03 | D24: =(1+Inputs!$C$7)^2 -> 1.0609 | E24: =(1+Inputs!$C$7)^3 -> 1.092727 | F24: =(1+Inputs!$C$7)^4 -> 1.1255088 | G24: =(1+Inputs!$C$7)^5 -> 1.1592741
A25: Precio | C25: =Inputs!$C$10*Calculos!$B$5*Calculos!$C$24 -> 4326 | D25: =Inputs!$C$10*Calculos!$B$5*Calculos!$D$24 -> 4455.78 | E25: =Inputs!$C$10*Calculos!$B$5*Calculos!$E$24 -> 4589.4534 | F25: =Inputs!$C$10*Calculos!$B$5*Calculos!$F$24 -> 4727.137 | G25: =Inputs!$C$10*Calculos!$B$5*Calculos!$G$24 -> 4868.9511
A26: Costo variable unitario | C26: =Calculos!$B$14*Calculos!$B$7*Calculos!$C$24 -> 2506.2722 | D26: =Calculos!$B$14*Calculos!$B$7*Calculos!$D$24 -> 2581.4604 | E26: =Calculos!$B$14*Calculos!$B$7*Calculos!$E$24 -> 2658.9042 | F26: =Calculos!$B$14*Calculos!$B$7*Calculos!$F$24 -> 2738.6713 | G26: =Calculos!$B$14*Calculos!$B$7*Calculos!$G$24 -> 2820.8315
A27: Ingresos | C27: =Calculos!$C$23*Calculos!$C$25 -> 68523840 | D27: =Calculos!$D$23*Calculos!$D$25 -> 70579555 | E27: =Calculos!$E$23*Calculos!$E$25 -> 72696942 | F27: =Calculos!$F$23*Calculos!$F$25 -> 74877850 | G27: =Calculos!$G$23*Calculos!$G$25 -> 77124186
A28: Costos variables | C28: =Calculos!$C$23*Calculos!$C$26 -> 39699352 | D28: =Calculos!$D$23*Calculos!$D$26 -> 40890333 | E28: =Calculos!$E$23*Calculos!$E$26 -> 42117042 | F28: =Calculos!$F$23*Calculos!$F$26 -> 43380554 | G28: =Calculos!$G$23*Calculos!$G$26 -> 44681970
A29: Costos fijos | C29: =Calculos!$B$15*12*Calculos!$B$8*Calculos!$C$24 -> 47382678 | D29: =Calculos!$B$15*12*Calculos!$B$8*Calculos!$D$24 -> 48804158 | E29: =Calculos!$B$15*12*Calculos!$B$8*Calculos!$E$24 -> 50268283 | F29: =Calculos!$B$15*12*Calculos!$B$8*Calculos!$F$24 -> 51776332 | G29: =Calculos!$B$15*12*Calculos!$B$8*Calculos!$G$24 -> 53329622
A30: EBITDA | C30: =Calculos!$C$27-Calculos!$C$28-Calculos!$C$29 -> -18558190 | D30: =Calculos!$D$27-Calculos!$D$28-Calculos!$D$29 -> -19114936 | E30: =Calculos!$E$27-Calculos!$E$28-Calculos!$E$29 -> -19688384 | F30: =Calculos!$F$27-Calculos!$F$28-Calculos!$F$29 -> -20279035 | G30: =Calculos!$G$27-Calculos!$G$28-Calculos!$G$29 -> -20887406
A31: Depreciación | C31: =Calculos!$B$18 -> 2718401.3 | D31: =Calculos!$B$18 -> 2718401.3 | E31: =Calculos!$B$18 -> 2718401.3 | F31: =Calculos!$B$18 -> 2718401.3 | G31: =Calculos!$B$18 -> 2718401.3
A32: EBIT | C32: =Calculos!$C$30-Calculos!$C$31 -> -21276591 | D32: =Calculos!$D$30-Calculos!$D$31 -> -21833337 | E32: =Calculos!$E$30-Calculos!$E$31 -> -22406785 | F32: =Calculos!$F$30-Calculos!$F$31 -> -22997437 | G32: =Calculos!$G$30-Calculos!$G$31 -> -23605808
A33: Pérdida tributaria inicial | C33: =0 -> 0 | D33: =Calculos!$C$36 -> 21276591 | E33: =Calculos!$D$36 -> 43109928 | F33: =Calculos!$E$36 -> 65516713 | G33: =Calculos!$F$36 -> 88514150
A34: Renta imponible | C34: =MAX(0,Calculos!$C$32-Calculos!$C$33) -> 0 | D34: =MAX(0,Calculos!$D$32-Calculos!$D$33) -> 0 | E34: =MAX(0,Calculos!$E$32-Calculos!$E$33) -> 0 | F34: =MAX(0,Calculos!$F$32-Calculos!$F$33) -> 0 | G34: =MAX(0,Calculos!$G$32-Calculos!$G$33) -> 0
A35: Impuesto | C35: =Calculos!$C$34*Inputs!$C$21 -> 0 | D35: =Calculos!$D$34*Inputs!$C$22 -> 0 | E35: =Calculos!$E$34*Inputs!$C$23 -> 0 | F35: =Calculos!$F$34*Inputs!$C$24 -> 0 | G35: =Calculos!$G$34*Inputs!$C$25 -> 0
A36: Pérdida tributaria final | C36: =MAX(0,Calculos!$C$33-Calculos!$C$32) -> 21276591 | D36: =MAX(0,Calculos!$D$33-Calculos!$D$32) -> 43109928 | E36: =MAX(0,Calculos!$E$33-Calculos!$E$32) -> 65516713 | F36: =MAX(0,Calculos!$F$33-Calculos!$F$32) -> 88514150 | G36: =MAX(0,Calculos!$G$33-Calculos!$G$32) -> 1.1211996e+08
A37: Capital de trabajo | C37: =Calculos!$C$27*Inputs!$C$47/365+Calculos!$C$28*Inputs!$C$48/365-Calculos!$C$28*Inputs!$C$49/365 -> 7263576.7 | D37: =Calculos!$D$27*Inputs!$C$47/365+Calculos!$D$28*Inputs!$C$48/365-Calculos!$D$28*Inputs!$C$49/365 -> 7481484 | E37: =Calculos!$E$27*Inputs!$C$47/365+Calculos!$E$28*Inputs!$C$48/365-Calculos!$E$28*Inputs!$C$49/365 -> 7705928.5 | F37: =Calculos!$F$27*Inputs!$C$47/365+Calculos!$F$28*Inputs!$C$48/365-Calculos!$F$28*Inputs!$C$49/365 -> 7937106.3 | G37: =Calculos!$G$27*Inputs!$C$47/365+Calculos!$G$28*Inputs!$C$48/365-Calculos!$G$28*Inputs!$C$49/365 -> 8175219.5
A38: Variación capital de trabajo | C38: =Calculos!$C$37-Calculos!$C$37 -> 0 | D38: =Calculos!$D$37-Calculos!$C$37 -> 217907.3 | E38: =Calculos!$E$37-Calculos!$D$37 -> 224444.52 | F38: =Calculos!$F$37-Calculos!$E$37 -> 231177.85 | G38: =Calculos!$G$37-Calculos!$F$37 -> 238113.19
A39: Recuperaciones terminales | C39: =0 -> 0 | D39: =0 -> 0 | E39: =0 -> 0 | F39: =0 -> 0 | G39: =Calculos!$B$19-MAX(0,(Calculos!$B$19-MAX(0,Calculos!$B$16-Calculos!$B$18*5)))*Inputs!$C$25+Calculos!$G$37+Calculos!$B$20 -> 12413061
A40: Flujo libre | B40: =-(Calculos!$B$17+Calculos!$B$20+Calculos!$C$37) -> -38467030 | C40: =Calculos!$C$30-Calculos!$C$35-Calculos!$C$38+Calculos!$C$39 -> -18558190 | D40: =Calculos!$D$30-Calculos!$D$35-Calculos!$D$38+Calculos!$D$39 -> -19332843 | E40: =Calculos!$E$30-Calculos!$E$35-Calculos!$E$38+Calculos!$E$39 -> -19912828 | F40: =Calculos!$F$30-Calculos!$F$35-Calculos!$F$38+Calculos!$F$39 -> -20510213 | G40: =Calculos!$G$30-Calculos!$G$35-Calculos!$G$38+Calculos!$G$39 -> -8712458.6
A41: Factor descuento | B41: 1 | C41: =1/(1+Inputs!$C$6)^1 -> 0.83015109 | D41: =1/(1+Inputs!$C$6)^2 -> 0.68915083 | E41: =1/(1+Inputs!$C$6)^3 -> 0.57209931 | F41: =1/(1+Inputs!$C$6)^4 -> 0.47492886 | G41: =1/(1+Inputs!$C$6)^5 -> 0.39426271
A42: Flujo descontado | B42: =Calculos!$B$40 -> -38467030 | C42: =Calculos!$C$40*Calculos!$C$41 -> -15406102 | D42: =Calculos!$D$40*Calculos!$D$41 -> -13323245 | E42: =Calculos!$E$40*Calculos!$E$41 -> -11392115 | F42: =Calculos!$F$40*Calculos!$F$41 -> -9740892.2 | G42: =Calculos!$G$40*Calculos!$G$41 -> -3434997.6
A43: Flujo acumulado | B43: =Calculos!$B$40 -> -38467030 | C43: =Calculos!$B$43+Calculos!$C$40 -> -57025220 | D43: =Calculos!$C$43+Calculos!$D$40 -> -76358063 | E43: =Calculos!$D$43+Calculos!$E$40 -> -96270891 | F43: =Calculos!$E$43+Calculos!$F$40 -> -1.167811e+08 | G43: =Calculos!$F$43+Calculos!$G$40 -> -1.2549356e+08
...

Sheet Listas
A1: Pesimista | C1: Origen de las validaciones del libro. No editar.
A2: Base
A3: Optimista

Sheet Tornado
A1: TORNADO · SENSIBILIDAD DE UNA VÍA
A2: Cada parámetro movido solo, entre su banda declarada. Ordenado por impacto en el VAN.
A4: Estado de esta hoja | B4: =IF(ABS(Calculos!$B$47-(-91764381.4776))>1,"DESACTUALIZADO — reejecute generar_modelo_excel.py","VIGENTE") -> VIGENTE
A5: Calculado el 2026-08-06 18:18 sobre VAN base -91,764,381 CLP.
A7: Parámetro | B7: Base | C7: Bajo | D7: Alto | E7: VAN bajo | F7: VAN alto | G7: Δ VAN | H7: Δ Fondeo | I7: Impacto | J7: Origen de la banda
A8: Precio B2B familiar | B8: 4200 | C8: 3024 | D8: 5040 | E8: -1.5044594e+08 | F8: -49848980 | G8: 1.0059696e+08 | H8: 1.6668189e+08 | I8: ██████████████████████ | J8: escenarios.precio_*_factor · PF Listo $3.017 / Meta Food $5.034
A9: Costo de personal | B9: 2393830 | C9: 1915064 | D9: 2872596 | E9: -73362995 | F9: -1.1016577e+08 | G9: 36802772 | H9: 62834129 | I9: ████████ | J9: swing exploratorio ±20% — sin banda publicada
A10: Capacidad instalada | B10: 60 | C10: 48 | D10: 72 | E10: -1.0878655e+08 | F10: -74742209 | G10: 34044345 | H10: 61213249 | I10: ███████ | J10: swing exploratorio ±20% — sin banda publicada
A11: Días de operación | B11: 22 | C11: 17.6 | D11: 26.4 | E11: -1.0878655e+08 | F11: -74742209 | G11: 34044345 | H11: 61213249 | I11: ███████ | J11: swing exploratorio ±20% — sin banda publicada
A12: Gramaje mozzarella | B12: 0.1 | C12: 0.08 | D12: 0.12 | E12: -82737609 | F12: -1.0079115e+08 | G12: 18053545 | H12: 30571623 | I12: ████ | J12: swing exploratorio ±20% — sin banda publicada
A13: Mozzarella $/kg | B13: 8403.36 | C13: 6722.69 | D13: 10084.03 | E13: -82737620 | F13: -1.0079114e+08 | G13: 18053523 | H13: 30571587 | I13: ████ | J13: swing exploratorio ±20% — sin banda publicada
A14: Arriendo mensual | B14: 759720 | C14: 607776 | D14: 911664 | E14: -85740333 | F14: -97788430 | G14: 12048097 | H14: 19941410 | I14: ███ | J14: swing exploratorio ±20% — sin banda publicada
A15: Otros ingredientes | B15: 550 | C15: 440 | D15: 660 | E15: -85856358 | F15: -97672405 | G15: 11816047 | H15: 20009131 | I15: ███ | J15: swing exploratorio ±20% — sin banda publicada
A16: TMAR | B16: 20.46 | C16: 16.368 | D16: 24.552 | E16: -96596196 | F16: -87564071 | G16: 9032125.1 | H16: 0 | I16: ██ | J16: swing exploratorio ±20% — sin banda publicada
A17: Habilitación sanitaria | B17: 12000000 | C17: 9600000 | D17: 15600000 | E17: -89113198 | F17: -95741157 | G17: 6627958.7 | H17: 6210000 | I17: █ | J17: AACE 18R-97 Clase 5 · escenarios.capex_*_factor
A18: Envolvente de equipos | B18: 10120237 | C18: 8096189.6 | D18: 13156308 | E18: -89193115 | F18: -95621281 | G18: 6428165.8 | H18: 6022806 | I18: █ | J18: AACE 18R-97 Clase 5 · escenarios.capex_*_factor
A19: Envase por unidad | B19: 300 | C19: 240 | D19: 360 | E19: -88695278 | F19: -94833485 | G19: 6138206.1 | H19: 10394354 | I19: █ | J19: swing exploratorio ±20% — sin banda publicada
... A21: Plazo de cobro | B21: 30 | C21: 30 | D21: 60 | E21: -91764381 | F21: -95271186 | G21: 3506804.8 | H21: 0 | I21: █ | J21: statement §8 · rango declarado 30–60 días
A22: Merma | B22: 5 | C22: 4 | D22: 6 | E22: -90890772 | F22: -92637991 | G22: 1747219.9 | H22: 2958718.1 | J22: swing exploratorio ±20% — sin banda publicada
A23: Contingencia | B23: 15 | C23: 12 | D23: 18 | E23: -91083192 | F23: -92445571 | G23: 1362378.2 | H23: 1276466.7 | J23: swing exploratorio ±20% — sin banda publicada
A24: Vida depreciable | B24: 10 | C24: 8 | D24: 12 | E24: -91764381 | F24: -91764381 | G24: 0 | H24: 0 | J24: swing exploratorio ±20% — sin banda publicada

Sheet Valores_Quiebre
A1: VALORES DE QUIEBRE
A2: Valor de cada parámetro que anula el VAN y valor que lleva el fondeo máximo al límite de capital.
A4: Estado de esta hoja | B4: =IF(ABS(Calculos!$B$47-(-91764381.4776))>1,"DESACTUALIZADO — reejecute generar_modelo_excel.py","VIGENTE") -> VIGENTE
A5: Calculado el 2026-08-06 18:18 sobre VAN base -91,764,381 CLP.
A6: El fondeo máximo actual ($125,493,563) supera el límite de $50,000,000. La columna «fondeo = límite» ya no marca un punto de quiebre sino la MEJORA REQUERIDA para volver a caber.
A8: Parámetro | B8: Base | C8: VAN = 0 | D8: Variación exigida | E8: Fondeo = límite | F8: Variación exigida | G8: Origen de la banda
A9: Precio B2B familiar | B9: 4200 | C9: 6151.6877 | D9: 0.46468754 | E9: SIN QUIEBRE EN EL RANGO | F9: — | G9: escenarios.precio_*_factor · PF Listo $3.017 / Meta Food $5.034
A10: Envolvente de equipos | B10: 10120237 | C10: SIN QUIEBRE EN EL RANGO | D10: — | E10: SIN QUIEBRE EN EL RANGO | F10: — | G10: AACE 18R-97 Clase 5 · escenarios.capex_*_factor
A11: Habilitación sanitaria | B11: 12000000 | C11: SIN QUIEBRE EN EL RANGO | D11: — | E11: SIN QUIEBRE EN EL RANGO | F11: — | G11: AACE 18R-97 Clase 5 · escenarios.capex_*_factor
A12: Plazo de cobro | B12: 30 | C12: SIN QUIEBRE EN EL RANGO | D12: — | E12: SIN QUIEBRE EN EL RANGO | F12: — | G12: statement §8 · rango declarado 30–60 días
A13: Capacidad instalada | B13: 60 | C13: 134.81996 | D13: 1.2469994 | E13: 95.567964 | F13: 0.5927994 | G13: swing exploratorio ±20% — sin banda publicada
A14: Días de operación | B14: 22 | C14: 49.433987 | D14: 1.2469994 | E14: 35.041587 | F14: 0.5927994 | G14: swing exploratorio ±20% — sin banda publicada
A15: Mozzarella $/kg | B15: 8403.36 | C15: SIN QUIEBRE EN EL RANGO | D15: — | E15: SIN QUIEBRE EN EL RANGO | F15: — | G15: swing exploratorio ±20% — sin banda publicada
A16: Gramaje mozzarella | B16: 0.1 | C16: SIN QUIEBRE EN EL RANGO | D16: — | E16: SIN QUIEBRE EN EL RANGO | F16: — | G16: swing exploratorio ±20% — sin banda publicada
A17: Costo de personal | B17: 2393830 | C17: SIN QUIEBRE EN EL RANGO | D17: — | E17: 1102366.4 | F17: -0.53949678 | G17: swing exploratorio ±20% — sin banda publicada
A18: Arriendo mensual | B18: 759720 | C18: SIN QUIEBRE EN EL RANGO | D18: — | E18: SIN QUIEBRE EN EL RANGO | F18: — | G18: swing exploratorio ±20% — sin banda publicada
A19: TMAR | B19: 20.46 | C19: SIN QUIEBRE EN EL RANGO | D19: — | E19: SIN QUIEBRE EN EL RANGO | F19: — | G19: swing exploratorio ±20% — sin banda publicada
A20: Contingencia | B20: 15 | C20: SIN QUIEBRE EN EL RANGO | D20: — | E20: SIN QUIEBRE EN EL RANGO | F20: — | G20: swing exploratorio ±20% — sin banda publicada
A21: Merma | B21: 5 | C21: SIN QUIEBRE EN EL RANGO | D21: — | E21: SIN QUIEBRE EN EL RANGO | F21: — | G21: swing exploratorio ±20% — sin banda publicada
A22: Vida depreciable | B22: 10 | C22: SIN QUIEBRE EN EL RANGO | D22: — | E22: SIN QUIEBRE EN EL RANGO | F22: — | G22: swing exploratorio ±20% — sin banda publicada
A23: Otros ingredientes | B23: 550 | C23: SIN QUIEBRE EN EL RANGO | D23: — | E23: SIN QUIEBRE EN EL RANGO | F23: — | G23: swing exploratorio ±20% — sin banda publicada
A24: Distribución por unidad | B24: 220 | C24: SIN QUIEBRE EN EL RANGO | D24: — | E24: SIN QUIEBRE EN EL RANGO | F24: — | G24: swing exploratorio ±20% — sin banda publicada
A25: Envase por unidad | B25: 300 | C25: SIN QUIEBRE EN EL RANGO | D25: — | E25: SIN QUIEBRE EN EL RANGO | F25: — | G25: swing exploratorio ±20% — sin banda publicada

Sheet Monte_Carlo
A1: MONTE CARLO · PERFIL DE RIESGO
A2: Distribuciones triangulares sobre los parámetros CON banda publicada. Semilla fija.
A4: PERFIL ILUSTRATIVO DE RIESGO. Las distribuciones son SUPUESTO; sólo sus anclas están citadas. No es evidencia y no altera ninguna conclusión del dossier. Los parámetros sin banda publicada quedan FUERA de la simulación: inventarles una distribución sería exactamente la cifra plausible que la regla 7 prohíbe.
A6: Estado de esta hoja | B6: =IF(ABS(Calculos!$B$47-(-91764381.4776))>1,"DESACTUALIZADO — reejecute generar_modelo_excel.py","VIGENTE") -> VIGENTE
A7: Calculado el 2026-08-06 18:18 sobre VAN base -91,764,381 CLP.
A9: Distribuciones simuladas
A10: Parámetro | B10: Mínimo | C10: Moda | D10: Máximo | E10: Ancla citada
A11: Precio B2B familiar | B11: 3024 | C11: 4200 | D11: 5040 | E11: escenarios.precio_*_factor · PF Listo $3.017 / Meta Food $5.034
A12: Envolvente de equipos | B12: 8096189.6 | C12: 10120237 | D12: 13156308 | E12: AACE 18R-97 Clase 5 · escenarios.capex_*_factor
A13: Habilitación sanitaria | B13: 9600000 | C13: 12000000 | D13: 15600000 | E13: AACE 18R-97 Clase 5 · escenarios.capex_*_factor
A14: Plazo de cobro | B14: 30 | C14: 30 | D14: 60 | E14: statement §8 · rango declarado 30–60 días
A17: Resultados
A18: Iteraciones | B18: 10000
A19: Semilla | B19: 20260804
A20: VAN P10 | B20: -1.2812973e+08
A21: VAN P50 (mediana) | B21: -98394492
A22: VAN P90 | B22: -73437127
A23: VAN medio | B23: -99590671
A24: P(VAN > 0) | B24: 0
A25: P(fondeo máximo ≤ límite de capital) | B25: 0
A28: Distribución del VAN
A29: Desde | B29: Hasta | C29: Casos | D29: Frecuencia
A30: -1.5365308e+08 | B30: -1.4842251e+08 | C30: 30 | D30: █
A31: -1.4842251e+08 | B31: -1.4319194e+08 | C31: 117 | D31: ███
A32: -1.4319194e+08 | B32: -1.3796138e+08 | C32: 179 | D32: █████
A33: -1.3796138e+08 | B33: -1.3273081e+08 | C33: 319 | D33: █████████
A34: -1.3273081e+08 | B34: -1.2750024e+08 | C34: 415 | D34: ████████████
A35: -1.2750024e+08 | B35: -1.2226968e+08 | C35: 459 | D35: █████████████
A36: -1.2226968e+08 | B36: -1.1703911e+08 | C36: 543 | D36: ████████████████
A37: -1.1703911e+08 | B37: -1.1180854e+08 | C37: 721 | D37: █████████████████████
A38: -1.1180854e+08 | B38: -1.0657797e+08 | C38: 774 | D38: ██████████████████████
A39: -1.0657797e+08 | B39: -1.0134741e+08 | C39: 896 | D39: ██████████████████████████
A40: -1.0134741e+08 | B40: -96116841 | C40: 943 | D40: ███████████████████████████
A41: -96116841 | B41: -90886274 | C41: 1040 | D41: ██████████████████████████████
... A49: -54272306 | B49: -49041739 | C49: 22 | D49: █

Sheet Tasa_Descuento
A1: TASA DE DESCUENTO
A2: Construcción de la TMAR y perfil del VAN frente a la tasa.
A4: Construcción declarada
A5: Componente | B5: % | C5: Nota
A6: TPM Banco Central | B6: 0.045 | C6: Tasa de política monetaria vigente a la fecha base.
A7: Interés corriente CMF 200–5.000 UF ≥90 días | B7: 0.2046 | C7: CMF Certificado 07/2026. Es lo que los bancos cobraron por dinero del tamaño y plazo del proyecto.
A8: Spread sobre TPM | B8: 0.1596 | C8: NO SE DESCOMPONE riesgo por riesgo: no hay fuente pública que lo permita. Se declara el spread observado, no una construcción inventada.
A9: TMAR usada por el modelo | B9: 0.2046 | C9: Piso observado. El capital propio es subordinado a esa deuda, así que la TMAR correcta es mayor; usar el piso es conservador respecto del rechazo.
A12: Perfil del VAN frente a la tasa (vivo)
A13: Tasa | B13: VAN | C13: Magnitud
A14: 0.05 | B14: =Calculos!$B$46*-1+Calculos!$B$40/(1+$A$14)^0+Calculos!$C$40/(1+$A$14)^1+Calculos!$D$40/(1+$A$14)^2+Calculos!$E$40/(1+$A$14)^3+Calculos!$F$40/(1+$A$14)^4+Calculos!$G$40/(1+$A$14)^5 -> -1.5304568e+08
A15: 0.08 | B15: =Calculos!$B$46*-1+Calculos!$B$40/(1+$A$15)^0+Calculos!$C$40/(1+$A$15)^1+Calculos!$D$40/(1+$A$15)^2+Calculos!$E$40/(1+$A$15)^3+Calculos!$F$40/(1+$A$15)^4+Calculos!$G$40/(1+$A$15)^5 -> -1.4750498e+08
A16: 0.11 | B16: =Calculos!$B$46*-1+Calculos!$B$40/(1+$A$16)^0+Calculos!$C$40/(1+$A$16)^1+Calculos!$D$40/(1+$A$16)^2+Calculos!$E$40/(1+$A$16)^3+Calculos!$F$40/(1+$A$16)^4+Calculos!$G$40/(1+$A$16)^5 -> -1.4258534e+08
A17: 0.14 | B17: =Calculos!$B$46*-1+Calculos!$B$40/(1+$A$17)^0+Calculos!$C$40/(1+$A$17)^1+Calculos!$D$40/(1+$A$17)^2+Calculos!$E$40/(1+$A$17)^3+Calculos!$F$40/(1+$A$17)^4+Calculos!$G$40/(1+$A$17)^5 -> -1.3819843e+08
A18: 0.17 | B18: =Calculos!$B$46*-1+Calculos!$B$40/(1+$A$18)^0+Calculos!$C$40/(1+$A$18)^1+Calculos!$D$40/(1+$A$18)^2+Calculos!$E$40/(1+$A$18)^3+Calculos!$F$40/(1+$A$18)^4+Calculos!$G$40/(1+$A$18)^5 -> -1.3427077e+08
A19: 0.2 | B19: =Calculos!$B$46*-1+Calculos!$B$40/(1+$A$19)^0+Calculos!$C$40/(1+$A$19)^1+Calculos!$D$40/(1+$A$19)^2+Calculos!$E$40/(1+$A$19)^3+Calculos!$F$40/(1+$A$19)^4+Calculos!$G$40/(1+$A$19)^5 -> -1.3074089e+08
A20: 0.23 | B20: =Calculos!$B$46*-1+Calculos!$B$40/(1+$A$20)^0+Calculos!$C$40/(1+$A$20)^1+Calculos!$D$40/(1+$A$20)^2+Calculos!$E$40/(1+$A$20)^3+Calculos!$F$40/(1+$A$20)^4+Calculos!$G$40/(1+$A$20)^5 -> -1.2755706e+08
A21: 0.26 | B21: =Calculos!$B$46*-1+Calculos!$B$40/(1+$A$21)^0+Calculos!$C$40/(1+$A$21)^1+Calculos!$D$40/(1+$A$21)^2+Calculos!$E$40/(1+$A$21)^3+Calculos!$F$40/(1+$A$21)^4+Calculos!$G$40/(1+$A$21)^5 -> -1.2467556e+08
A22: 0.29 | B22: =Calculos!$B$46*-1+Calculos!$B$40/(1+$A$22)^0+Calculos!$C$40/(1+$A$22)^1+Calculos!$D$40/(1+$A$22)^2+Calculos!$E$40/(1+$A$22)^3+Calculos!$F$40/(1+$A$22)^4+Calculos!$G$40/(1+$A$22)^5 -> -1.2205928e+08
A23: 0.32 | B23: =Calculos!$B$46*-1+Calculos!$B$40/(1+$A$23)^0+Calculos!$C$40/(1+$A$23)^1+Calculos!$D$40/(1+$A$23)^2+Calculos!$E$40/(1+$A$23)^3+Calculos!$F$40/(1+$A$23)^4+Calculos!$G$40/(1+$A$23)^5 -> -1.1967651e+08
A24: 0.35 | B24: =Calculos!$B$46*-1+Calculos!$B$40/(1+$A$24)^0+Calculos!$C$40/(1+$A$24)^1+Calculos!$D$40/(1+$A$24)^2+Calculos!$E$40/(1+$A$24)^3+Calculos!$F$40/(1+$A$24)^4+Calculos!$G$40/(1+$A$24)^5 -> -1.1750012e+08

Sheet Estructura_Capital
A1: ESTRUCTURA DE CAPITAL
A2: Configuraciones comparadas contra dos techos de capital: $30.000.000 y $50.000.000.
A4: Estado de esta hoja | B4: =IF(ABS(Calculos!$B$47-(-91764381.4776))>1,"DESACTUALIZADO — reejecute generar_modelo_excel.py","VIGENTE") -> VIGENTE
A5: Calculado el 2026-08-06 18:18 sobre VAN base -91,764,381 CLP.
